Workbook

Sheet Дано
A1: Тип документа: | B1: Отчет
A2: Номер отчета: | B2: 001-01/20
A3: Основание оценки: | B3: ="Договор №"&B2&" от "&TEXT(B4,"[$-ru-RU-x-genlower]ДД ММММ ГГГГ \г\.;@") -> Договор №001-01/20 от 01 января 2020 г.
A4: Дата оценки (осмотра): | B4: 01 января 2020 г.
A5: Дата составления отчета: | B5: 07 января 2020 г.
A6: Заказчик (полностью): | B6: Навальный Алексей «ФБК»
A7: Идентификация прав: | B7: Частная собственность
A8: Место осмотра: | B8: г. Бишкек
A9: Цель оценки: | B9: Определение стоимости причиненного ущерба
A10: Назначение результатов: | B10: Для возмещения убытков (ст. 14 ГК КР)
A11: Вид стоимости: | B11: Рыночная стоимость восстановления транспортного средства
A12: Подходы и методы: | B12: Метод поэлементного расчета затратного подхода и метод рыночной информации сравнительного подхода
A13: Сумма оплаты цифрами, сом: | B13: 2500
A14: Сумма оплаты прописью, сом: | B14: Две тысячи пятьсот
A16: Объект оценки: | B16: Транспортное средство
A17: Марка, модель: | B17: Subaru Outback
A18: Рег. (гос.) номер: | B18: 08KG848ААА
A19: Кузов (VIN) №: | B19: JTJTJ884888488848
A20: Рама (шасси) №: | B20: -
A21: Тех. паспорт №: | B21: КР 8848884
A22: Год выпуска: | B22: 2088
A23: Объем ДВС (в куб. см): | B23: 2498
A24: Пробег (указать ед. изм.): | B24: Н/у
A25: Цвет: | B25: Пурпурный
A26: Тип ТС / кузова: | B26: Легковой седан
A27: Тип КПП: | B27: Автоматическая
A28: Положение руля: | B28: Слева
A29: Владелец: | B29: =B6 -> Навальный Алексей «ФБК»
A30: Адрес регистрации: | B30: г. Бишкек, 88 мкр-н, 8-48
A32: Курс USD/KGS: | B32: 75
A33: Нормо-час, сом: | B33: 550
A34: Результат цифрами, сом: | B34: 888880
A35: Результат прописью, сом: | B35: Восемьсот восемьдесят восемь тысяч восемьсот восемьдесят

Sheet счёт
A1: ОсОО "Первый Автосервис", г. Бишкек, ул. Атбашинская, 2/1; ИНН 01501201910391; Р/с 1091805549830135; БЦФ ОАО «Оптима Банк»; БИК 109018; УГНС по Первомайскому району (004); Тел. +996 (550) 560 220, +996 (706) 560 220, +996 (776) 560 220
A4: Счет на оплату № | D4: =Дано!B2 -> 001-01/20 | H4: =Дано!B4 -> 01 января 2020 г.
A7: Покупатель: | C7: =Дано!B6 -> Навальный Алексей «ФБК»
A9: Основание: | C9: =Дано!B3 -> Договор №001-01/20 от 01 января 2020 г.
A11: Получил: | C11: ____________________________________
A13: № | B13: Код товара | C13: Наименование товара (работы, услуги) | G13: Единица измерения | H13: Количество | I13: Цена отпускная | J13: Сумма отпускная
A15: 1 | B15: 00001 | C15: ="Экспертиза и оценка: "&Дано!B16&" "&Дано!B17&", "&Дано!B18 -> Экспертиза и оценка: Транспортное средство Subaru Outback, 08KG848ААА | G15: шт. | H15: 1 | I15: =Дано!B13 -> 2500 | J15: =I15*H15 -> 2500
A17: Итого к оплате, сом | J17: =J15 -> 2500
A19: 1. Компания является плательщиком по упрощенной системе налогообложения на основе единого налога (ст.357 НК КР)
A21: 2. Компания не является плательщиком НДС (ст.228 НК КР)
A23: Итого к оплате: | C23: =Дано!B14&" сом, 00 тыйын" -> Две тысячи пятьсот сом, 00 тыйын
C26: Руководитель _________________________
B28: М.П.
A38: =A1 -> ОсОО "Первый Автосервис", г. Бишкек, ул. Атбашинская, 2/1; ИНН 01501201910391; Р/с 1091805549830135; БЦФ ОАО «Оптима Банк»; БИК 109018; УГНС по Первомайскому району (004); Тел. +996 (550) 560 220, +996 (706) 560 220, +996 (776) 560 220
A41: Счет на оплату № | D41: =D4 -> 001-01/20 | H41: =H4 -> 01 января 2020 г.
A44: Покупатель: | C44: =C7 -> Навальный Алексей «ФБК»
A46: Основание: | C46: =C9 -> Договор №001-01/20 от 01 января 2020 г.
A48: Получил: | C48: =C11 -> ____________________________________
A50: № | B50: Код товара | C50: Наименование товара (работы, услуги) | G50: Единица измерения | H50: Количество | I50: Цена отпускная | J50: Сумма отпускная
A52: 1 | B52: =B15 -> 00001 | C52: =C15 -> Экспертиза и оценка: Транспортное средство Subaru Outback, 08KG848ААА | G52: =G15 -> шт. | H52: =H15 -> 1 | I52: =I15 -> 2500 | J52: =I52*H52 -> 2500
A54: Итого к оплате, сом | J54: =J52 -> 2500
A56: 1. Компания является плательщиком по упрощенной системе налогообложения на основе единого налога (ст.357 НК КР)
A58: 2. Компания не является плательщиком НДС (ст.228 НК КР)
A60: Итого к оплате: | C60: =C23 -> Две тысячи пятьсот сом, 00 тыйын
C63: Руководитель _________________________
B65: М.П.

Sheet факт
A1: =счёт!A1 -> ОсОО "Первый Автосервис", г. Бишкек, ул. Атбашинская, 2/1; ИНН 01501201910391; Р/с 1091805549830135; БЦФ ОАО «Оптима Банк»; БИК 109018; УГНС по Первомайскому району (004); Тел. +996 (550) 560 220, +996 (706) 560 220, +996 (776) 560 220
A4: Счет-фактура № | D4: =счёт!D4 -> 001-01/20 | H4: =счёт!H4 -> 01 января 2020 г.
A7: Покупатель: | C7: =счёт!C7 -> Навальный Алексей «ФБК»
A9: Основание: | C9: =счёт!C9 -> Договор №001-01/20 от 01 января 2020 г.
A11: Получил: | C11: ____________________________________
A13: № | B13: Код товара | C13: Наименование товара (работы, услуги) | G13: Единица измерения | H13: Количество | I13: Цена отпускная | J13: Сумма отпускная
A15: 1 | B15: =счёт!B15:B16 -> 00001 | C15: =счёт!C15 -> Экспертиза и оценка: Транспортное средство Subaru Outback, 08KG848ААА | G15: шт. | H15: =счёт!H15 -> 1 | I15: =счёт!I15 -> 2500 | J15: =I15*H15 -> 2500
A17: Итого к оплате, сом | J17: =J15 -> 2500
A19: 1. Компания является плательщиком по упрощенной системе налогообложения на основе единого налога (ст.357 НК КР)
A21: 2. Компания не является плательщиком НДС (ст.228 НК КР)
A23: Итого к оплате: | C23: =счёт!C23 -> Две тысячи пятьсот сом, 00 тыйын
C26: Руководитель _________________________
B28: М.П.
A38: =A1 -> ОсОО "Первый Автосервис", г. Бишкек, ул. Атбашинская, 2/1; ИНН 01501201910391; Р/с 1091805549830135; БЦФ ОАО «Оптима Банк»; БИК 109018; УГНС по Первомайскому району (004); Тел. +996 (550) 560 220, +996 (706) 560 220, +996 (776) 560 220
A41: Счет-фактура № | D41: =D4 -> 001-01/20 | H41: =H4 -> 01 января 2020 г.
A44: Покупатель: | C44: =C7 -> Навальный Алексей «ФБК»
A46: Основание: | C46: =C9 -> Договор №001-01/20 от 01 января 2020 г.
A48: Получил: | C48: =C11 -> ____________________________________
A50: № | B50: Код товара | C50: Наименование товара (работы, услуги) | G50: Единица измерения | H50: Количество | I50: Цена отпускная | J50: Сумма отпускная
A52: 1 | B52: =B15 -> 00001 | C52: =C15 -> Экспертиза и оценка: Транспортное средство Subaru Outback, 08KG848ААА | G52: =G15 -> шт. | H52: =H15 -> 1 | I52: =I15 -> 2500 | J52: =I52*H52 -> 2500
A54: Итого к оплате, сом | J54: =J52 -> 2500
A56: 1. Компания является плательщиком по упрощенной системе налогообложения на основе единого налога (ст.357 НК КР)
A58: 2. Компания не является плательщиком НДС (ст.228 НК КР)
A60: Итого к оплате: | C60: =C23 -> Две тысячи пятьсот сом, 00 тыйын
C63: Руководитель _________________________
B65: М.П.

Sheet прих
A1: ОсОО "Первый Автосервис" | H1: Форма КО-1 | K1: ЛИНИЯ ОТРЕЗА | L1: ОсОО "Первый Автосервис"
A2: предприятие, организация | L2: предприятие, организация
H3: Код по ОКУД
L4: КВИТАНЦИЯ
A5: ПРИХОДНЫЙ КАССОВЫЙ ОРДЕР | L5: к приходному кассовому ордеру
A6: Номер документа | B6: Дата составления | E6: Корреспонди-рующий счет, субсчет | F6: Код аналитического учета | G6: Сумма сом., тыйын | H6: Код целевого назначения | L6: № | M6: =A11 -> 001-01/20
L8: Принято от:
L9: =C14 -> Навальный Алексей «ФБК»
A11: =факт!D4 -> 001-01/20 | B11: =L23 -> 01 января 2020 г. | G11: =факт!J17 -> 2500
L12: Основание:
L13: =C17 -> Договор №001-01/20 от 01 января 2020 г.
A14: Принято от: | C14: =факт!C7 -> Навальный Алексей «ФБК»
L16: Сумма:
A17: Основание: | C17: =факт!C9 -> Договор №001-01/20 от 01 января 2020 г. | L17: =C20 -> Две тысячи пятьсот сом, 00 тыйын
A20: Сумма: | C20: =факт!C23 -> Две тысячи пятьсот сом, 00 тыйын | L20: =G11 -> 2500 | M20: сом | N20: 00 | O20: тыйын
A23: Приложение: | C23: =факт!C15 -> Экспертиза и оценка: Транспортное средство Subaru Outback, 08KG848ААА | L23: =факт!H4 -> 01 января 2020 г.
L26: М.П.
A29: Руководитель ________________ | L29: Руководитель ________________

Sheet акт
A1: ="Акт о приемке выполненных работ №"&счёт!D4 -> Акт о приемке выполненных работ №001-01/20
A2: ="от "&факт!H4 -> от 01 января 2020 г.
A4: Исполнитель: | B4: ОсОО «Первый Автосервис»
A6: Заказчик: | B6: =Дано!B6 -> Навальный Алексей «ФБК»
A8: № отчёта | B8: Марка, модель | C8: Регистр. номер | D8: Стоимость за отчёт, сом
A9: =Дано!B2 -> 001-01/20 | B9: =Дано!B17 -> Subaru Outback | C9: =Дано!B18 -> 08KG848ААА | D9: =Дано!B13 -> 2500
A10: Итого на сумму: | D10: =SUM(D9:D9) -> 2500
A12: ="Всего оказано услуг на сумму: "&D10&",00 ("&Дано!B14&" сом, 00 тыйын)." -> Всего оказано услуг на сумму: 2500,00 (Две тысячи пятьсот сом, 00 тыйын).
A14: Вышеперечисленные работы (услуги) выполнены полностью и в срок.
A16: Заказчик претензий по объему, качеству и срокам оказания услуг претензий не имеет.
A19: Исполнитель _________________________ | C19: Заказчик _________________________
A20: М.П. | C20: М.П.

Sheet Ущерб
A1: № | B1: Услуги | C1: Кол-во | D1: Нормо-час | E1: Стоимость | G1: Услуги | H1: Материалы | I1: Запчасти | J1: УТС | K1: Итого, сом | L1: Итого, $
G2: 0 | H2: 0 | I2: 0 | J2: =УТС!H2 -> 0 | K2: =G2+H2+I2+J2 -> 0 | L2: =ROUND(K2/Дано!B32,2) -> 0
G3: Автоматически

Sheet Средн
A1: № | B1: Контакт | C1: Стоимость, $ | D1: Стоимость, сом
A2: 1 | B2: +996 | C2: 0 | D2: =ROUND(C2*Дано!$B$32,-2) -> 0
A3: 2 | B3: +996 | C3: 0 | D3: =ROUND(C3*Дано!$B$32,-2) -> 0
A4: 3 | B4: +996 | C4: 0 | D4: =ROUND(C4*Дано!$B$32,-2) -> 0
A5: 4 | B5: +996 | C5: 0 | D5: =ROUND(C5*Дано!$B$32,-2) -> 0
A6: 5 | B6: +996 | C6: 0 | D6: =ROUND(C6*Дано!$B$32,-2) -> 0
A7: 6 | B7: +996 | C7: 0 | D7: =ROUND(C7*Дано!$B$32,-2) -> 0
A8: 7 | B8: +996 | C8: 0 | D8: =ROUND(C8*Дано!$B$32,-2) -> 0
A9: 8 | B9: +996 | C9: 0 | D9: =ROUND(C9*Дано!$B$32,-2) -> 0
A10: 9 | B10: +996 | C10: 0 | D10: =ROUND(C10*Дано!$B$32,-2) -> 0
A11: 10 | B11: +996 | C11: 0 | D11: =ROUND(C11*Дано!$B$32,-2) -> 0
A12: 11 | B12: +996 | C12: 0 | D12: =ROUND(C12*Дано!$B$32,-2) -> 0
A13: 12 | B13: +996 | C13: 0 | D13: =ROUND(C13*Дано!$B$32,-2) -> 0
... A21: 20 | B21: +996 | C21: 0 | D21: =ROUND(C21*Дано!$B$32,-2) -> 0
C22: =AVERAGE(C2:C21) -> 0 | D22: =AVERAGE(D2:D21) -> 0

Sheet УТС
A1: № | B1: Ремонтное воздействие | C1: Кол-во | D1: % | E1: Стоимость | G1: % | H1: Стоимость
G2: 0 | H2: 0
G3: Авто | H3: $
G4: 0 | H4: =ROUND(H2/Дано!B32,2) -> 0

Sheet Утиль
A1: Для легковых | E1: Кз | F1: Кв | G1: Коп
A2: Наименование агрегата, узла, детали | B2: Сi, % | C2: Сго, сом | E2: 0.7 | F2: 0.5 | G2: 0.75
E3: Авто Сi, % | F3: Сi, % | G3: Сго, сом
B76: =SUM(B3:B75) -> 0 | C76: =SUM(C3:C75) -> 0
A78: Для легковых (расширенный)
A79: Наименование агрегата, узла, детали | B79: Сi, % | C79: Сго, сом
A80: Кузовные детали, экстерьер, интерьер, в т.ч.: | B80: 50 | C80: =ROUND(($E$2*$F$2*$G$2*Средн!$D$22*B80)/100,2) -> 0 | D80: 45 <1>
A81: Передняя часть: | B81: 14 | C81: =ROUND(($E$2*$F$2*$G$2*Средн!$D$22*B81)/100,2) -> 0
A82: Капот | B82: 1.9 | C82: =ROUND(($E$2*$F$2*$G$2*Средн!$D$22*B82)/100,2) -> 0
A83: Крыло переднее (за 1 шт.) | B83: 0.8 | C83: =ROUND(($E$2*$F$2*$G$2*Средн!$D$22*B83)/100,2) -> 0
A84: Бампер передний (в сборе с усилителем, накладками и молдингами, спойлером) | B84: 1.9 | C84: =ROUND(($E$2*$F$2*$G$2*Средн!$D$22*B84)/100,2) -> 0
A85: Решетка (облицовка) радиатора | B85: 0.8 | C85: =ROUND(($E$2*$F$2*$G$2*Средн!$D$22*B85)/100,2) -> 0
A86: Лонжерон передний (за 1 шт.) | B86: 0.8 | C86: =ROUND(($E$2*$F$2*$G$2*Средн!$D$22*B86)/100,2) -> 0
A87: Брызговик крыла (за 1 шт.) | B87: 1.4 | C87: =ROUND(($E$2*$F$2*$G$2*Средн!$D$22*B87)/100,2) -> 0
A88: Стекло ветрового окна | B88: 1.7 | C88: =ROUND(($E$2*$F$2*$G$2*Средн!$D$22*B88)/100,2) -> 0
A89: Рамка радиатора | B89: 1.4 | C89: =ROUND(($E$2*$F$2*$G$2*Средн!$D$22*B89)/100,2) -> 0
A90: Щиток передка | B90: 0.3 | C90: =ROUND(($E$2*$F$2*$G$2*Средн!$D$22*B90)/100,2) -> 0
A91: Задняя часть: | B91: 12 | C91: =ROUND(($E$2*$F$2*$G$2*Средн!$D$22*B91)/100,2) -> 0 | D91: 14 <1>
A92: Бампер задний | B92: 1.6 | C92: =ROUND(($E$2*$F$2*$G$2*Средн!$D$22*B92)/100,2) -> 0
A93: Крыло заднее (боковина <1>) в сборе с арками (за 1 шт.) | B93: 2.1 | C93: =ROUND(($E$2*$F$2*$G$2*Средн!$D$22*B93)/100,2) -> 0 | D93: 3,1 <1>
A94: Стекло окна задка | B94: 1.9 | C94: =ROUND(($E$2*$F$2*$G$2*Средн!$D$22*B94)/100,2) -> 0
A95: Панель задка | B95: 0.8 | C95: =ROUND(($E$2*$F$2*$G$2*Средн!$D$22*B95)/100,2) -> 0
A96: Пол багажника | B96: 0.8 | C96: =ROUND(($E$2*$F$2*$G$2*Средн!$D$22*B96)/100,2) -> 0
A97: Облицовки багажника | B97: 1.1 | C97: =ROUND(($E$2*$F$2*$G$2*Средн!$D$22*B97)/100,2) -> 0
A98: Крышка багажника (дверь задка) | B98: 1.6 | C98: =ROUND(($E$2*$F$2*$G$2*Средн!$D$22*B98)/100,2) -> 0
A99: Средняя часть: | B99: 24 | C99: =ROUND(($E$2*$F$2*$G$2*Средн!$D$22*B99)/100,2) -> 0 | D99: 17 <1>
A100: Передняя стойка боковины (за 1 шт.) | B100: 1.4 | C100: =ROUND(($E$2*$F$2*$G$2*Средн!$D$22*B100)/100,2) -> 0
A101: Средняя стойка боковины с порогом и частью пола (за 1 шт.) | B101: 1.4 | C101: =ROUND(($E$2*$F$2*$G$2*Средн!$D$22*B101)/100,2) -> 0 | D101: 0 <1>
A102: Облицовки стоек боковины, порогов, уплотнители, центральная консоль, противосолнечные козырьки, плафоны освещения, коврики пола, зеркало заднего вида | B102: 2.5 | C102: =ROUND(($E$2*$F$2*$G$2*Средн!$D$22*B102)/100,2) -> 0 | D102: 2,1 <1>
A103: Двери в сборе с арматурой (за 1 шт.), | B103: 1.9 | C103: =ROUND(($E$2*$F$2*$G$2*Средн!$D$22*B103)/100,2) -> 0
A104: в т.ч. арматура дверей (за 1 дверной комплект) | B104: 0.5 | C104: =ROUND(($E$2*$F$2*$G$2*Средн!$D$22*B104)/100,2) -> 0
A105: Сиденья (все) | B105: 1.1 | C105: =ROUND(($E$2*$F$2*$G$2*Средн!$D$22*B105)/100,2) -> 0
A106: Панель крыши в сб. с обивкой, поперечинами и верх. частями стоек, | B106: 3.5 | C106: =ROUND(($E$2*$F$2*$G$2*Средн!$D$22*B106)/100,2) -> 0
A107: в т.ч. обивка панели крыши | B107: 0.8 | C107: =ROUND(($E$2*$F$2*$G$2*Средн!$D$22*B107)/100,2) -> 0
A108: Панель приборов в сборе с щитком приборов, решетками, вещевым ящиком, карманами и т.д. | B108: 2.5 | C108: =ROUND(($E$2*$F$2*$G$2*Средн!$D$22*B108)/100,2) -> 0
A109: Ремень безопасности передний (за 1 шт.) | B109: 0.3 | C109: =ROUND(($E$2*$F$2*$G$2*Средн!$D$22*B109)/100,2) -> 0
A110: Подушка безопасности пассажирская | B110: 0.6 | C110: =ROUND(($E$2*$F$2*$G$2*Средн!$D$22*B110)/100,2) -> 0
A111: Двигатель, навесное, охлаждение, впускная и выпускная система | B111: 11 | C111: =ROUND(($E$2*$F$2*$G$2*Средн!$D$22*B111)/100,2) -> 0 | D111: 13 <2>
A112: Двигатель в сборе без навесного оборудования | B112: 4.9 | C112: =ROUND(($E$2*$F$2*$G$2*Средн!$D$22*B112)/100,2) -> 0
A113: в т.ч. клапанная крышка | B113: 0.5 | C113: =ROUND(($E$2*$F$2*$G$2*Средн!$D$22*B113)/100,2) -> 0
...

Sheet Рынок
A1: Наименование | B1: Объект оценки | C1: Аналог 1 | D1: Аналог 2 | E1: Аналог 3 | F1: Аналог 4
A2: Дата оценки | B2: 43831 | C2: 43831 | D2: 43831 | E2: 43831 | F2: 43831
A3: Источник | B3: См. Акт осмотра | C3: +996 | D3: +996 | E3: +996 | F3: +996
A4: Марка, модель | B4: =Дано!B17 -> Subaru Outback | C4: =$B$4 -> Subaru Outback | D4: =$B$4 -> Subaru Outback | E4: =$B$4 -> Subaru Outback | F4: =$B$4 -> Subaru Outback
A5: Год выпуска | B5: =Дано!B22 -> 2088 | C5: =$B$5 -> 2088 | D5: =$B$5 -> 2088 | E5: =$B$5 -> 2088 | F5: =$B$5 -> 2088
A6: Краткое описание | B6: Хорошее состояние, 3,0 турбодизель, монитор, полный электропакет, 888 888 км, торг | C6: Хорошее состояние, 3,0 турбодизель, монитор, полный электропакет, 888 888 км, торг | D6: Хорошее состояние, 3,0 турбодизель, монитор, полный электропакет, 888 888 км, торг | E6: Хорошее состояние, 3,0 турбодизель, монитор, полный электропакет, 888 888 км, торг | F6: Хорошее состояние, 3,0 турбодизель, монитор, полный электропакет, 888 888 км, торг
A7: Цена предложения, сом | C7: 0 | D7: 0 | E7: 0 | F7: 0
A8: Наименование корректировки | C8: Аналог 1 | D8: Аналог 2 | E8: Аналог 3 | F8: Аналог 4
A9: на торг (скидку) | C9: 1 | D9: 1 | E9: 1 | F9: 1
A10: скорректированная цена аналога, сом | C10: =C7*C9 -> 0 | D10: =D7*D9 -> 0 | E10: =E7*E9 -> 0 | F10: =F7*F9 -> 0
A11: на пробег и год выпуска | C11: 1 | D11: 1 | E11: 1 | F11: 1
A12: скорректированная цена аналога, сом | C12: =C10*C11 -> 0 | D12: =D10*D11 -> 0 | E12: =E10*E11 -> 0 | F12: =F10*F11 -> 0
A13: на состояние кузова и салона | C13: 1 | D13: 1 | E13: 1 | F13: 1
A14: скорректированная цена аналога, сом | C14: =C12*C13 -> 0 | D14: =D12*D13 -> 0 | E14: =E12*E13 -> 0 | F14: =F12*F13 -> 0
A15: на состояние двигателя и трансмиссии | C15: 1 | D15: 1 | E15: 1 | F15: 1
A16: скорректированная цена аналога, сом | C16: =C14*C15 -> 0 | D16: =D14*D15 -> 0 | E16: =E14*E15 -> 0 | F16: =F14*F15 -> 0
A17: на тип трансмиссии | C17: 1 | D17: 1 | E17: 1 | F17: 1
A18: скорректированная цена аналога, сом | C18: =C16*C17 -> 0 | D18: =D16*D17 -> 0 | E18: =E16*E17 -> 0 | F18: =F16*F17 -> 0
A19: на комплектацию | C19: 1 | D19: 1 | E19: 1 | F19: 1
A20: скорректированная цена аналога, сом | C20: =C18*C19 -> 0 | D20: =D18*D19 -> 0 | E20: =E18*E19 -> 0 | F20: =F18*F19 -> 0
A21: Стоимость объекта оценки, сом | C21: =ROUND(AVERAGE(C20:F20),-2) -> 0
